Error linking document 28: Can't attach instance <MedicalDocument at 0x7f6bc7ff6a10>; another instance with key (<class 'models.MedicalDocument'>, (28,), None) is already present in this session.
  ⚠️  FINAL CORRECTION: Complete status to Incomplete for Eye Exam - no documents successfully linked
/home/runner/workspace/automated_screening_routes.py:163: SAWarning: Object of type <MedicalDocument> not in session, add operation along 'Screening.documents' won't proceed (This warning originated from the Session 'autoflush' process, which was invoked automatically in response to a user-initiated operation. Consider using ``no_autoflush`` context manager if this warning happended while initializing objects.)
  ).first()
  → Linked document Garcia_pap_smear_results.pdf to screening Pap Smear
  → Linked document HbA1c_Test_Results_2024.pdf to screening HbA1c Test
  → Error linking document 32: Can't attach instance <MedicalDocument at 0x7f6bc7f72790>; another instance with key (<class 'models.MedicalDocument'>, (32,), None) is already present in this session.
/home/runner/workspace/automated_screening_routes.py:259: SAWarning: Object of type <MedicalDocument> not in session, add operation along 'Screening.documents' won't proceed (This warning originated from the Session 'autoflush' process, which was invoked automatically in response to a user-initiated operation. Consider using ``no_autoflush`` context manager if this warning happended while initializing objects.)
  existing_doc = db.session.get(MedicalDocument, document.id)
  → Linked document Eichel_pap_smear_results.pdf to screening Pap Smear
  → Error linking document 12: Can't attach instance <MedicalDocument at 0x7f6bc7e00890>; another instance with key (<class 'models.MedicalDocument'>, (12,), None) is already present in this session.
  → Linked document Eichel_a1c_glucose_results.pdf to screening HbA1c Test
  → Linked document Juntunen_colonoscopy_report_2024.pdf to screening Colonoscopy
  → Linked document Juntunen_lipid_panel_results.pdf to screening Lipid Panel
  → Error linking document 22: Can't attach instance <MedicalDocument at 0x7f6bc7e01450>; another instance with key (<class 'models.MedicalDocument'>, (22,), None) is already present in this session.
  ⚠️  FINAL CORRECTION: Complete status to Incomplete for Eye Exam - no documents successfully linked
  → Error linking document 39: Can't attach instance <MedicalDocument at 0x7f6bc7e03610>; another instance with key (<class 'models.MedicalDocument'>, (39,), None) is already present in this session.
  → Linked document Davis_gastroenterology_consultation.pdf to screening Colonoscopy
  → Error linking document 19: Can't attach instance <MedicalDocument at 0x7f6bc7e00150>; another instance with key (<class 'models.MedicalDocument'>, (19,), None) is already present in this session.
  → Linked document Davis_lipid_panel_results.pdf to screening Lipid Panel
  → Error linking document 45: Can't attach instance <MedicalDocument at 0x7f6bcd1edad0>; another instance with key (<class 'models.MedicalDocument'>, (45,), None) is already present in this session.
  ⚠️  FINAL CORRECTION: Complete status to Incomplete for Eye Exam - no documents successfully linked
  → Linked document Martinez_ct_colonography.pdf to screening Colonoscopy
  → Linked document Martinez_lipid_panel_lab_results.pdf to screening Lipid Panel
  → Linked document Martinez_dexa_scan_bone_density.pdf to screening Bone Density Screening
  → Error linking document 99: Can't attach instance <MedicalDocument at 0x7f6bcd153ad0>; another instance with key (<class 'models.MedicalDocument'>, (99,), None) is already present in this session.
  ⚠️  FINAL CORRECTION: Complete status to Incomplete for Pap Smear - no documents successfully linked
  → Error linking document 93: Can't attach instance <MedicalDocument at 0x7f6bcd151350>; another instance with key (<class 'models.MedicalDocument'>, (93,), None) is already present in this session.
/home/runner/workspace/automated_screening_routes.py:234: SAWarning: Object of type <MedicalDocument> not in session, add operation along 'Screening.documents' won't proceed
  db.session.commit()
  → Error linking document 117: Can't attach instance <MedicalDocument at 0x7f6bc7ffc7d0>; another instance with key (<class 'models.MedicalDocument'>, (117,), None) is already present in this session.
[2025-07-13 14:34:38 +0000] [608] [CRITICAL] WORKER TIMEOUT (pid:621)
{"timestamp": "2025-07-13T14:34:38.054128Z", "level": "ERROR", "logger": "app", "message": "Rolling back due to exception: 1", "module": "app", "function": "teardown_request", "line": 181, "thread": 140101497320960, "process": 621, "request": {"method": "GET", "path": "/screenings", "remote_addr": "10.82.11.130", "user_agent": "Mozilla/5.0 (Macintosh; Intel Mac OS X 10_15_7) AppleWebKit/537.36 (KHTML, like Gecko) Replit/1.0.14 Chrome/124.0.6367.119 Electron/30.0.3 Safari/537.36", "endpoint": "screening_list"}, "session": {"session_id": "6YMSZoSujap9SCuwhHAfucklnDA8E0lmokqh2PsNEuE", "user_id": null, "username": null}, "security": {"ip_address": "10.82.11.130", "user_agent": "Mozilla/5.0 (Macintosh; Intel Mac OS X 10_15_7) AppleWebKit/537.36 (KHTML, like Gecko) Replit/1.0.14 Chrome/124.0.6367.119 Electron/30.0.3 Safari/537.36", "timestamp": 1752417247.8438962}}
{"timestamp": "2025-07-13T14:34:38.055111Z", "level": "ERROR", "logger": "app", "message": "Rolling back due to exception: 1", "module": "app", "function": "teardown_request", "line": 181, "thread": 140101497320960, "process": 621, "request": {"method": "GET", "path": "/screenings", "remote_addr": "10.82.11.130", "user_agent": "Mozilla/5.0 (Macintosh; Intel Mac OS X 10_15_7) AppleWebKit/537.36 (KHTML, like Gecko) Replit/1.0.14 Chrome/124.0.6367.119 Electron/30.0.3 Safari/537.36", "endpoint": "screening_list"}, "session": {"session_id": "6YMSZoSujap9SCuwhHAfucklnDA8E0lmokqh2PsNEuE", "user_id": null, "username": null}, "security": {"ip_address": "10.82.11.130", "user_agent": "Mozilla/5.0 (Macintosh; Intel Mac OS X 10_15_7) AppleWebKit/537.36 (KHTML, like Gecko) Replit/1.0.14 Chrome/124.0.6367.119 Electron/30.0.3 Safari/537.36", "timestamp": 1752417247.8438962}}
[2025-07-13 14:34:38 +0000] [621] [ERROR] Error handling request /screenings?tab=screenings&regenerate=true&search=
Traceback (most recent call last):
  File "/home/runner/workspace/.pythonlibs/lib/python3.11/site-packages/gunicorn/workers/sync.py", line 134, in handle
    self.handle_request(listener, req, client, addr)
  File "/home/runner/workspace/.pythonlibs/lib/python3.11/site-packages/gunicorn/workers/sync.py", line 177, in handle_request
    respiter = self.wsgi(environ, resp.start_response)
               ^^^^^^^^^^^^^^^^^^^^^^^^^^^^^^^^^^^^^^^
  File "/home/runner/workspace/.pythonlibs/lib/python3.11/site-packages/flask/app.py", line 1536, in __call__
    return self.wsgi_app(environ, start_response)
           ^^^^^^^^^^^^^^^^^^^^^^^^^^^^^^^^^^^^^^
  File "/home/runner/workspace/.pythonlibs/lib/python3.11/site-packages/werkzeug/middleware/proxy_fix.py", line 183, in __call__
    return self.app(environ, start_response)
           ^^^^^^^^^^^^^^^^^^^^^^^^^^^^^^^^^
  File "/home/runner/workspace/.pythonlibs/lib/python3.11/site-packages/flask/app.py", line 1511, in wsgi_app
    response = self.full_dispatch_request()
               ^^^^^^^^^^^^^^^^^^^^^^^^^^^^
  File "/home/runner/workspace/.pythonlibs/lib/python3.11/site-packages/flask/app.py", line 917, in full_dispatch_request
    rv = self.dispatch_request()
         ^^^^^^^^^^^^^^^^^^^^^^^
  File "/home/runner/workspace/.pythonlibs/lib/python3.11/site-packages/flask/app.py", line 902, in dispatch_request
    return self.ensure_sync(self.view_functions[rule.endpoint])(**view_args)  # type: ignore[no-any-return]
           ^^^^^^^^^^^^^^^^^^^^^^^^^^^^^^^^^^^^^^^^^^^^^^^^^^^^^^^^^^^^^^^^^
  File "/home/runner/workspace/demo_routes.py", line 3327, in screening_list
    _update_patient_screenings(patient_id, screening_data)
  File "/home/runner/workspace/automated_screening_routes.py", line 182, in _update_patient_screenings
    for doc in existing.documents.all():
               ^^^^^^^^^^^^^^^^^^^^^^^^
  File "/home/runner/workspace/.pythonlibs/lib/python3.11/site-packages/sqlalchemy/orm/query.py", line 2704, in all
    return self._iter().all()  # type: ignore
           ^^^^^^^^^^^^
  File "/home/runner/workspace/.pythonlibs/lib/python3.11/site-packages/sqlalchemy/orm/dynamic.py", line 151, in _iter
    sess = self.session
           ^^^^^^^^^^^^
  File "/home/runner/workspace/.pythonlibs/lib/python3.11/site-packages/sqlalchemy/orm/dynamic.py", line 140, in session
    sess.flush()
  File "/home/runner/workspace/.pythonlibs/lib/python3.11/site-packages/sqlalchemy/orm/session.py", line 4353, in flush
    self._flush(objects)
  File "/home/runner/workspace/.pythonlibs/lib/python3.11/site-packages/sqlalchemy/orm/session.py", line 4488, in _flush
    with util.safe_reraise():
  File "/home/runner/workspace/.pythonlibs/lib/python3.11/site-packages/sqlalchemy/util/langhelpers.py", line 146, in __exit__
    raise exc_value.with_traceback(exc_tb)
  File "/home/runner/workspace/.pythonlibs/lib/python3.11/site-packages/sqlalchemy/orm/session.py", line 4449, in _flush
    flush_context.execute()
  File "/home/runner/workspace/.pythonlibs/lib/python3.11/site-packages/sqlalchemy/orm/unitofwork.py", line 466, in execute
    rec.execute(self)
  File "/home/runner/workspace/.pythonlibs/lib/python3.11/site-packages/sqlalchemy/orm/unitofwork.py", line 642, in execute
    util.preloaded.orm_persistence.save_obj(
  File "/home/runner/workspace/.pythonlibs/lib/python3.11/site-packages/sqlalchemy/orm/persistence.py", line 85, in save_obj
    _emit_update_statements(
  File "/home/runner/workspace/.pythonlibs/lib/python3.11/site-packages/sqlalchemy/orm/persistence.py", line 912, in _emit_update_statements
    c = connection.execute(
        ^^^^^^^^^^^^^^^^^^^
  File "/home/runner/workspace/.pythonlibs/lib/python3.11/site-packages/sqlalchemy/engine/base.py", line 1416, in execute
    return meth(
           ^^^^^
  File "/home/runner/workspace/.pythonlibs/lib/python3.11/site-packages/sqlalchemy/sql/elements.py", line 523, in _execute_on_connection
    return connection._execute_clauseelement(
           ^^^^^^^^^^^^^^^^^^^^^^^^^^^^^^^^^^
  File "/home/runner/workspace/.pythonlibs/lib/python3.11/site-packages/sqlalchemy/engine/base.py", line 1638, in _execute_clauseelement
    ret = self._execute_context(
          ^^^^^^^^^^^^^^^^^^^^^^
  File "/home/runner/workspace/.pythonlibs/lib/python3.11/site-packages/sqlalchemy/engine/base.py", line 1843, in _execute_context
    return self._exec_single_context(
           ^^^^^^^^^^^^^^^^^^^^^^^^^^
  File "/home/runner/workspace/.pythonlibs/lib/python3.11/site-packages/sqlalchemy/engine/base.py", line 1983, in _exec_single_context
    self._handle_dbapi_exception(
  File "/home/runner/workspace/.pythonlibs/lib/python3.11/site-packages/sqlalchemy/engine/base.py", line 2355, in _handle_dbapi_exception
    raise exc_info[1].with_traceback(exc_info[2])
  File "/home/runner/workspace/.pythonlibs/lib/python3.11/site-packages/sqlalchemy/engine/base.py", line 1964, in _exec_single_context
    self.dialect.do_execute(
  File "/home/runner/workspace/.pythonlibs/lib/python3.11/site-packages/sqlalchemy/engine/default.py", line 945, in do_execute
    cursor.execute(statement, parameters)
  File "/nix/store/clx0mcir7qw8zk36zbr4jra789g3knf6-python3-3.11.10/lib/python3.11/encodings/utf_8.py", line 15, in decode
    def decode(input, errors='strict'):
    
  File "/home/runner/workspace/.pythonlibs/lib/python3.11/site-packages/gunicorn/workers/base.py", line 204, in handle_abort
    sys.exit(1)
SystemExit: 1