{"timestamp": "2025-06-05T22:32:13.814128Z", "level": "WARNING", "logger": "cache_manager", "message": "Redis not available, using memory cache: Error 99 connecting to localhost:6379. Cannot assign requested address.", "module": "cache_manager", "function": "init_app", "line": 41, "thread": 140505087057472, "process": 3967}
[2025-06-05 22:32:16 +0000] [3967] [ERROR] Exception in worker process
Traceback (most recent call last):
  File "/home/runner/workspace/.pythonlibs/lib/python3.11/site-packages/gunicorn/arbiter.py", line 608, in spawn_worker
    worker.init_process()
  File "/home/runner/workspace/.pythonlibs/lib/python3.11/site-packages/gunicorn/workers/base.py", line 135, in init_process
    self.load_wsgi()
  File "/home/runner/workspace/.pythonlibs/lib/python3.11/site-packages/gunicorn/workers/base.py", line 147, in load_wsgi
    self.wsgi = self.app.wsgi()
                ^^^^^^^^^^^^^^^
  File "/home/runner/workspace/.pythonlibs/lib/python3.11/site-packages/gunicorn/app/base.py", line 66, in wsgi
    self.callable = self.load()
                    ^^^^^^^^^^^
  File "/home/runner/workspace/.pythonlibs/lib/python3.11/site-packages/gunicorn/app/wsgiapp.py", line 57, in load
    return self.load_wsgiapp()
           ^^^^^^^^^^^^^^^^^^^
  File "/home/runner/workspace/.pythonlibs/lib/python3.11/site-packages/gunicorn/app/wsgiapp.py", line 47, in load_wsgiapp
    return util.import_app(self.app_uri)
           ^^^^^^^^^^^^^^^^^^^^^^^^^^^^^
  File "/home/runner/workspace/.pythonlibs/lib/python3.11/site-packages/gunicorn/util.py", line 370, in import_app
    mod = importlib.import_module(module)
          ^^^^^^^^^^^^^^^^^^^^^^^^^^^^^^^
  File "/nix/store/clx0mcir7qw8zk36zbr4jra789g3knf6-python3-3.11.10/lib/python3.11/importlib/__init__.py", line 126, in import_module
    return _bootstrap._gcd_import(name[level:], package, level)
           ^^^^^^^^^^^^^^^^^^^^^^^^^^^^^^^^^^^^^^^^^^^^^^^^^^^^
  File "<frozen importlib._bootstrap>", line 1204, in _gcd_import
  File "<frozen importlib._bootstrap>", line 1176, in _find_and_load
  File "<frozen importlib._bootstrap>", line 1147, in _find_and_load_unlocked
  File "<frozen importlib._bootstrap>", line 690, in _load_unlocked
  File "<frozen importlib._bootstrap_external>", line 940, in exec_module
  File "<frozen importlib._bootstrap>", line 241, in _call_with_frames_removed
  File "/home/runner/workspace/main.py", line 8, in <module>
    import demo_routes  # noqa: F401
    ^^^^^^^^^^^^^^^^^^
  File "/home/runner/workspace/demo_routes.py", line 107, in <module>
    @cache_route('dashboard', ttl=60, vary_on=['selected_date', 'date_str', 'refresh'])
     ^^^^^^^^^^^
NameError: name 'cache_route' is not defined
[2025-06-05 22:32:16 +0000] [3967] [INFO] Worker exiting (pid: 3967)
[2025-06-05 22:32:17 +0000] [3954] [ERROR] Worker (pid:3967) exited with code 3
[2025-06-05 22:32:17 +0000] [3954] [ERROR] Shutting down: Master
[2025-06-05 22:32:17 +0000] [3954] [ERROR] Reason: Worker failed to boot.